Workbook
Name _Toc301930468: TestDesign!#REF!
Name _Toc301930478: TestDesign!#REF!
Name ACTION: #REF!
Name ACTION: #REF!
Name LOCAL_DATE_SEPARATOR: #REF!
Name LOCAL_DATE_SEPARATOR: #REF!
Name LOCAL_DAY_FORMAT: #REF!
Name LOCAL_DAY_FORMAT: #REF!
Name LOCAL_HOUR_FORMAT: #REF!
Name LOCAL_HOUR_FORMAT: #REF!
Name LOCAL_MINUTE_FORMAT: #REF!
Name LOCAL_MINUTE_FORMAT: #REF!
Name LOCAL_MONTH_FORMAT: #REF!
Name LOCAL_MONTH_FORMAT: #REF!
Name LOCAL_SECOND_FORMAT: #REF!
Name LOCAL_SECOND_FORMAT: #REF!
Name LOCAL_TIME_SEPARATOR: #REF!
Name LOCAL_TIME_SEPARATOR: #REF!
Name LOCAL_YEAR_FORMAT: #REF!
Name LOCAL_YEAR_FORMAT: #REF!

Sheet Cover
B2: TEST CASE
B4: Project Name | C4: FPT-SHOP | F4: Creator | G4: Trần Minh Tường
B5: Project Code | C5: FPT-SHOP | F5: Reviewer/Approver | G5: Trần Thụy Minh Thư
B6: Document Code | C6: =C5&"_TestCase" -> FPT-SHOP_TestCase | F6: Issue Date | G6: 15/12/2024
F7: Version | G7: 0.2
B10: Record of change
B11: Effective Date | C11: Version | D11: Change Item | E11: *A,D,M | F11: Change description | G11: Reference
B12: 45302 | C12: 0.1 | E12: A | F12: Create sample file of Test Desgin
B13: 45516 | C13: 0.2 | E13: A,D,M | F13: Create sample file of TestCase for fucntion Confirm Order
B14: 15/12/2024 | C14: 0.3 | E14: M | F14: Complete writing testcase

Sheet Test case List
D1: TEST CASE LIST
B3: Project Name | D3: =Cover!C4 -> FPT-SHOP
B4: Project Code | D4: =Cover!C5 -> FPT-SHOP
B5: Test Environment Setup Description
B8: No | C8: Function Name | D8: Sheet Name | E8: Description | F8: Pre-Condition
B9: 1 | C9: ConfirmOrder | D9: TestCase | E9: This testcase is writing for function Confirm order with the interface available

Sheet TestDesign
A1: Requirement Level 1 | B1: Requirement Level 2 | C1: Requirement Level 3 | D1: Test Criteria | E1: Test Type | F1: Note
A2: Đặt hàng | B2: Hiển thị sản phẩm | C2: Hiển thị thông tin sản phẩm | D2: Đảm bảo hình ảnh, tên, màu sắc và giá sản phẩm hiển thị chính xác. | E2: GUI | F2: Kiểm tra rằng tất cả chi tiết sản phẩm đều rõ ràng và chính xác.
D3: Xác minh hình ảnh và mô tả sản phẩm khớp với chi tiết sản phẩm đã chọn. | E3: GUI
D4: Đảm bảo sản phẩm sẵn có và hiển thị đúng khi tải trang. | E4: GUI
B5: Thông tin khách hàng | C5: Nhập thông tin khách hàng | D5: Kiểm tra các trường thông tin (Họ và Tên, Số điện thoại, Email) được nhập đúng và hợp lệ. | E5: Function
D6: Đảm bảo các trường bắt buộc không được để trống. | E6: Function
D7: Kiểm tra định dạng email tuân thủ chuẩn (ví dụ: user@example.com). | E7: Function
D8: Kiểm tra số điện thoại có đúng 10 số và bắt đầu bằng số 0. | E8: Function
D9: Hiển thị cảnh báo nếu tên vượt quá 50 ký tự. | E9: Function
B10: Tùy chọn giao hàng | C10: Giao hàng tận nơi | D10: Kiểm tra người dùng có thể chọn địa chỉ giao hàng và khung giờ. | E10: Function | F10: Có thể chọn người nhận thay thế nếu cần.
D11: Cho phép thêm địa chỉ giao hàng mới và lưu vào tài khoản. | E11: Function
D12: Xác minh người dùng có thể chọn địa chỉ giao hàng từ danh sách đã lưu. | E12: Function
C13: Nhận tại cửa hàng | D13: Kiểm tra người dùng có thể chọn địa điểm cửa hàng và yêu cầu hỗ trợ kỹ thuật (nếu cần). | E13: Function | F13: Cửa hàng phải thuộc danh sách hợp lệ.
D14: Đảm bảo ngày và giờ nhận hàng được hiển thị theo thời gian thực. | E14: Function
D15: Xác minh người dùng có thể chọn cửa hàng gần nhất và hiển thị giờ hoạt động. | E15: Function
B16: Mã giảm giá và điểm thưởng | C16: Áp dụng mã giảm giá | D16: Mã giảm giá phải hợp lệ và chưa hết hạn. | E16: Function | F16: Hiển thị thông báo ngay nếu mã giảm giá không hợp lệ hoặc đã hết hạn.
D17: Hiển thị thông báo lỗi nếu mã giảm giá không hợp lệ hoặc hết hạn. | E17: Function
C18: Sử dụng điểm thưởng | D18: Người dùng phải đăng nhập và số điểm sử dụng không được vượt quá số dư. | E18: Function | F18: Điểm thưởng được quy đổi thành giảm giá.
D19: Xác minh hệ thống không cho phép sử dụng đồng thời điểm thưởng và mã giảm giá nếu bị hạn chế. | E19: Function
B20: Xuất hóa đơn điện tử | C20: Hóa đơn công ty | D20: Nhập đúng tên công ty, mã số thuế và địa chỉ hợp lệ. | E20: Function | F20: Bắt buộc nếu chọn loại hóa đơn công ty.
C21: Hóa đơn cá nhân | D21: Nhập địa chỉ và email hợp lệ để nhận hóa đơn. | E21: Function | F21: Định dạng địa chỉ và email phải đúng.
B22: Thanh toán | C22: Thẻ tín dụng/Ghi nợ | D22: Đảm bảo thông tin thẻ hợp lệ (số thẻ, ngày hết hạn, CVV). | E22: Function | F22: Hỗ trợ Visa, MasterCard, Amex.
C23: Ví điện tử | D23: Đăng nhập vào tài khoản ví điện tử và xác minh. | E23: Function | F23: Hỗ trợ MoMo, ZaloPay, Apple Pay.
C24: Chuyển khoản ngân hàng | D24: Thực hiện theo hướng dẫn chuyển khoản và xác nhận. | E24: Function
C25: Thanh toán khi nhận hàng | D25: Kiểm tra khu vực áp dụng cho phương thức thanh toán này. | E25: Function
B26: Xác nhận đơn hàng | C26: Xác nhận thông tin | D26: Đảm bảo thông tin chính xác trước khi nhấn [Đặt hàng] | E26: Function | F26: Xác nhận người dùng đồng ý với điều khoản sử dụng dịch vụ.
D27: Xác nhận người dùng nhận được thông báo xác nhận đơn hàng sau khi đặt thành công. | E27: Function
D28: Đảm bảo người dùng đồng ý với các điều khoản và điều kiện trước khi đặt hàng. | E28: Function
D29: Kiểm tra nút [Đặt hàng] hoạt động và chuyển hướng đến màn hình xác nhận. | E29: Function

Sheet TestCase
A2: Module Code | B2: ORD | L2: Passed
A3: Test requirement | B3: Đặt hàng | L3: Failed
A4: Tester | B4: Trần Minh Tường | L4: Blocked
A5: Passed | B5: Failed | D5: Untested | F5: Blocked | G5: Skipped | H5: Number of Test cases | L5: Untested
A6: =COUNTIF(H9:H995,"Passed") -> 27 | B6: =COUNTIF(H9:H995,"Failed") -> 23 | D6: =COUNTIF(H$9:H$995,"Untested") -> 0 | F6: =COUNTIF(H$9:H$995,"Blocked") -> 0 | G6: =COUNTIF(H$9:H$995,"Skipped") -> 0 | H6: =COUNTA(A9:A995) -> 50 | L6: Skipped
A8: ID | B8: Test Case Description | C8: Preconditions | D8: Test Case Procedure | E8: Test Data | F8: Expected Output | G8: Inter-test case Dependence | H8: Result | I8: Test date | J8: Note | K8: Evidence
A9: ORD_Add_100 | B9: Thêm địa chỉ giao hàng thành công | C9: 1. Truy cập vào trang web: ""https://fptshop.com.vn/"" thành công 2. Chọn vào sản phẩm cần mua 3. Chọn vào [Mua ngay] hoặc [🛒] để thêm sản phẩm vào giỏ hàng. 4. Chọn vào [Xác nhận đơn] để đến trang nhập thông tin và đặt hàng | D9: "1. Điều hướng đến trang tùy chọn giao hàng. 2. Thêm địa chỉ giao hàng mới và lưu lại." | E9: Tên người nhận: minh tường - Số điện thoại: 0847881229 - Địa chỉ: 1 Nguyễn Thái Học, Phường Nguyễn Thái Bình, Quận 1, Hồ Chí Minh | F9: Địa chỉ giao hàng mới được thêm và lưu lại thành công. | G9: None | H9: Passed | I9: 15/12/2024
A10: ORD_Add_200 | B10: Thêm và áp dụng mã giảm giá hợp lệ | C10: 1. Truy cập vào trang web: ""https://fptshop.com.vn/"" thành công 2. Chọn vào sản phẩm cần mua 3. Chọn vào [Mua ngay] hoặc [🛒] để thêm sản phẩm vào giỏ hàng. 4. Chọn vào [Xác nhận đơn] để đến trang nhập thông tin và đặt hàng | D10: 1. Điều hướng đến trang thanh toán. 2. Nhập mã giảm giá hợp lệ. 3. Nhấn nút [Áp dụng mã]. | E10: Mã giảm giá: SAVE20 - Giá trị giảm giá: 20% | F10: Mã giảm giá được áp dụng thành công và tổng tiền cập nhật chính xác. | G10: None | H10: Failed | I10: 15/12/2024
A11: ORD_Add_300 | B11: Thêm địa chỉ giao hàng mới | C11: 1. Truy cập vào trang web: ""https://fptshop.com.vn/"" thành công 2. Chọn vào sản phẩm cần mua 3. Chọn vào [Mua ngay] hoặc [🛒] để thêm sản phẩm vào giỏ hàng. 4. Chọn vào [Xác nhận đơn] để đến trang nhập thông tin và đặt hàng | D11: 1. Điều hướng đến trang tùy chọn giao hàng. 2. Nhập đầy đủ thông tin địa chỉ giao hàng mới (tên người nhận, số điện thoại, địa chỉ chi tiết). 3. Nhấn nút [[Xác nhận] địa chỉ]. | E11: Tên người nhận: Minh Tường - Số điện thoại: 0847881229 - Địa chỉ: 1, Phường Hòa Khánh Bắc, Quận Liên Chiểu, Đà Nẵng | F11: Địa chỉ giao hàng mới được thêm thành công. | G11: None | H11: Passed | I11: 15/12/2024
A12: ORD_Add_400 | B12: Thêm và chọn địa chỉ giao hàng mới cho đơn hàng | C12: 1. Truy cập vào trang web: ""https://fptshop.com.vn/"" thành công 2. Chọn vào sản phẩm cần mua 3. Chọn vào [Mua ngay] hoặc [🛒] để thêm sản phẩm vào giỏ hàng. 4. Chọn vào [Xác nhận đơn] để đến trang nhập thông tin và đặt hàng | D12: 1. Điều hướng đến trang tùy chọn giao hàng. 2. Thêm địa chỉ mới. 3. Chọn địa chỉ vừa thêm cho đơn hàng bằng cách nhấn nút [Chọn địa chỉ này]. | E12: Tên người nhận: Minh Tường - Số điện thoại: 0847881229 - Địa chỉ: 1, Phường Hòa Khánh Bắc, Quận Liên Chiểu, Đà Nẵng | F12: Địa chỉ giao hàng mới được chọn thành công cho đơn hàng. | G12: Depends on ORD_Add_001 | H12: Passed | I12: 15/12/2024
A13: ORD_Add_500 | B13: Thêm địa chỉ giao hàng mới trong quá trình thanh toán | C13: 1. Truy cập vào trang web: ""https://fptshop.com.vn/"" thành công 2. Chọn vào sản phẩm cần mua 3. Chọn vào [Mua ngay] hoặc [🛒] để thêm sản phẩm vào giỏ hàng. 4. Chọn vào [Xác nhận đơn] để đến trang nhập thông tin và đặt hàng | D13: 1. Điều hướng đến trang tùy chọn giao hàng. 2. Nhấn nút [Thay đổi]. 3. Nhập địa chỉ hợp lệ (đường, thành phố, mã bưu chính, v.v.). 4. Lưu lại địa chỉ mới. | E13: Địa chỉ: 1, Phường Hòa Khánh Bắc, Quận Liên Chiểu, Đà Nẵng | F13: Địa chỉ giao hàng mới được thêm và lưu lại thành công. | G13: None | H13: Failed | I13: 15/12/2024
A14: ORD_Add_600 | B14: Thêm mã giảm giá hợp lệ vào đơn hàng | C14: 1. Truy cập vào trang web: ""https://fptshop.com.vn/"" thành công 2. Chọn vào sản phẩm cần mua 3. Chọn vào [Mua ngay] hoặc [🛒] để thêm sản phẩm vào giỏ hàng. 4. Chọn vào [Xác nhận đơn] để đến trang nhập thông tin và đặt hàng | D14: 1. Điều hướng đến trang thanh toán. 2. Nhập mã giảm giá hợp lệ vào ô [Nhập mã giảm giá]. 3. Nhấn nút [Áp dụng]. 4. Xác minh tổng tiền cập nhật đúng với giá trị giảm giá.. | E14: Mã giảm giá: SAVE20 - Giá trị giảm giá: 20% | F14: Mã giảm giá được áp dụng thành công và tổng tiền được cập nhật chính xác. | G14: None | H14: Failed | I14: 15/12/2024
A15: ORD_Add_700 | B15: Thêm phương thức thanh toán bằng thẻ tín dụng | C15: 1. Truy cập vào trang web: ""https://fptshop.com.vn/"" thành công 2. Chọn vào sản phẩm cần mua 3. Chọn vào [Mua ngay] hoặc [🛒] để thêm sản phẩm vào giỏ hàng. 4. Chọn vào [Xác nhận đơn] để đến trang nhập thông tin và đặt hàng | D15: 1. Điều hướng đến trang thanh toán. 2. Nhập thông tin thẻ tín dụng hợp lệ (số thẻ, ngày hết hạn, CVV). 3. Nhấn nút [Thêm phương thức thanh toán]. 4. Xác minh rằng phương thức thanh toán được thêm thành công. | E15: Số thẻ:123456712123111 - Ngày hết hạn: 12/25 - CVV: 123 | F15: hương thức thanh toán bằng thẻ tín dụng được thêm thành công. | G15: None | H15: Failed | I15: 15/12/2024
A16: ORD_Add_800 | B16: Thêm điểm thưởng mới vào đơn hàng | C16: 1. Truy cập vào trang web: ""https://fptshop.com.vn/"" thành công 2. Chọn vào sản phẩm cần mua 3. Chọn vào [Mua ngay] hoặc [🛒] để thêm sản phẩm vào giỏ hàng. 4. Chọn vào [Xác nhận đơn] để đến trang nhập thông tin và đặt hàng | D16: 1. Đăng nhập vào tài khoản có điểm thưởng. 2. Điều hướng đến trang thanh toán. 3. Áp dụng điểm thưởng vào đơn hàng. 4. Xác minh điểm thưởng được áp dụng chính xác. | F16: Điểm thưởng được áp dụng thành công, tổng tiền được giảm đúng giá trị điểm thưởng | G16: None | H16: Failed | I16: 15/12/2024
A17: ORD_Add_900 | B17: Thêm ngày và khung giờ giao hàng mới | C17: 1. Truy cập vào trang web: ""https://fptshop.com.vn/"" thành công 2. Chọn vào sản phẩm cần mua 3. Chọn vào [Mua ngay] hoặc [🛒] để thêm sản phẩm vào giỏ hàng. 4. Chọn vào [Xác nhận đơn] để đến trang nhập thông tin và đặt hàng | D17: 1. Điều hướng đến trang tùy chọn giao hàng. 2. Chọn ngày giao hàng mới. 3. Chọn một khung giờ khả dụng. 4. Xác minh rằng ngày và khung giờ đã được áp dụng.. | F17: Ngày và khung giờ giao hàng được cập nhật thành công. | G17: None | H17: Passed | I17: 15/12/2024
A18: ORD_Check_001 | B18: Kiểm tra hiển thị chi tiết sản phẩm | C18: 1. Truy cập vào trang web: ""https://fptshop.com.vn/"" thành công 2. Chọn vào sản phẩm cần mua 3. Chọn vào [Mua ngay] hoặc [🛒] để thêm sản phẩm vào giỏ hàng. 4. Chọn vào [Xác nhận đơn] để đến trang nhập thông tin và đặt hàng | D18: 1. Điều hướng đến trang chi tiết sản phẩm. 2. Kiểm tra xem hình ảnh, tên, màu sắc và giá của sản phẩm có hiển thị chính xác hay không. | F18: Hình ảnh và thông tin chi tiết của sản phẩm hiển thị chính xác. | G18: None | H18: Passed | I18: 15/12/2024
A19: ORD_Check_002 | B19: Kiểm tra xác thực email thất bại với email không hợp lệ | C19: 1. Truy cập vào trang web: ""https://fptshop.com.vn/"" thành công 2. Chọn vào sản phẩm cần mua 3. Chọn vào [Mua ngay] hoặc [🛒] để thêm sản phẩm vào giỏ hàng. 4. Chọn vào [Xác nhận đơn] để đến trang nhập thông tin và đặt hàng | D19: 1. Nhập địa chỉ email không hợp lệ (ví dụ: abc.com). 2. Nhấn nút lưu. | E19: Email không hợp lệ: abc.com | F19: Hiển thị thông báo lỗi: "Định dạng email không hợp lệ." | G19: None | H19: Passed | I19: 15/12/2024
A20: ORD_Check_003 | B20: Kiểm tra mã giảm giá thất bại với mã không hợp lệ/hết hạn | C20: 1. Truy cập vào trang web: ""https://fptshop.com.vn/"" thành công 2. Chọn vào sản phẩm cần mua 3. Chọn vào [Mua ngay] hoặc [🛒] để thêm sản phẩm vào giỏ hàng. 4. Chọn vào [Xác nhận đơn] để đến trang nhập thông tin và đặt hàng | D20: 1. Nhập mã giảm giá hết hạn hoặc không hợp lệ. 2. Nhấn nút [Áp dụng mã]. | E20: Mã giảm giá: SAVE20 - Giá trị giảm giá: 20% | F20: Hiển thị thông báo lỗi: "Mã giảm giá không hợp lệ hoặc đã hết hạn."" | G20: None | H20: Failed | I20: 15/12/2024
A21: ORD_Check_004 | B21: Kiểm tra điểm thưởng thất bại khi vượt quá số dư hiện tại | C21: 1. Truy cập vào trang web: ""https://fptshop.com.vn/"" thành công 2. Chọn vào sản phẩm cần mua 3. Chọn vào [Mua ngay] hoặc [🛒] để thêm sản phẩm vào giỏ hàng. 4. Chọn vào [Xác nhận đơn] để đến trang nhập thông tin và đặt hàng | D21: 1. Đăng nhập vào tài khoản có điểm thưởng. 2. Áp dụng điểm thưởng vượt quá số dư hiện tại. | F21: Hiển thị thông báo lỗi: "Số điểm thưởng không đủ để sử dụng." | G21: None | H21: Failed | I21: 15/12/2024
A22: ORD_Check_005 | B22: Kiểm tra cập nhật khung giờ giao hàng theo thời gian thực | C22: 1. Truy cập vào trang web: ""https://fptshop.com.vn/"" thành công 2. Chọn vào sản phẩm cần mua 3. Chọn vào [Mua ngay] hoặc [🛒] để thêm sản phẩm vào giỏ hàng. 4. Chọn vào [Xác nhận đơn] để đến trang nhập thông tin và đặt hàng | D22: 1. Điều hướng đến trang tùy chọn giao hàng. 2. Chọn một ngày giao hàng. 3. Kiểm tra rằng khung giờ được cập nhật động. | F22: Khung giờ giao hàng được cập nhật đúng theo ngày đã chọn. | G22: Depends on ORD_Add_001 | H22: Passed | I22: 15/12/2024
A23: ORD_Check_006 | B23: Kiểm tra hiển thị thông báo xác nhận đơn hàng | C23: 1. Truy cập vào trang web: ""https://fptshop.com.vn/"" thành công 2. Chọn vào sản phẩm cần mua 3. Chọn vào [Mua ngay] hoặc [🛒] để thêm sản phẩm vào giỏ hàng. 4. Chọn vào [Xác nhận đơn] để đến trang nhập thông tin và đặt hàng | D23: 1. Hoàn thành tất cả các trường thông tin bắt buộc (địa chỉ giao hàng, phương thức thanh toán, v.v.). 2. Nhấn nút [Đặt hàng]. | F23: Thông báo xác nhận hiển thị, xác nhận rằng đơn hàng đã được đặt thành công. | G23: Depends on ORD_Add_001, ORD_Add_002 | H23: Passed | I23: 15/12/2024
A24: ORD_Check_007 | B24: Kiểm tra thông báo lỗi khi không nhập địa chỉ giao hàng | C24: 1. Truy cập vào trang web: ""https://fptshop.com.vn/"" thành công 2. Chọn vào sản phẩm cần mua 3. Chọn vào [Mua ngay] hoặc [🛒] để thêm sản phẩm vào giỏ hàng. 4. Chọn vào [Xác nhận đơn] để đến trang nhập thông tin và đặt hàng | D24: 1. Điều hướng đến trang tùy chọn giao hàng. 2. Để trống trường địa chỉ giao hàng và nhấn nút [Đặt hàng]. | F24: Hiển thị thông báo lỗi: "Vui lòng nhập địa chỉ giao hàng." | G24: None | H24: Passed | I24: 15/12/2024
A25: ORD_Check_008 | B25: Kiểm tra hệ thống ngăn cản đặt hàng khi thiếu thông tin | C25: 1. Truy cập vào trang web: ""https://fptshop.com.vn/"" thành công 2. Chọn vào sản phẩm cần mua 3. Chọn vào [Mua ngay] hoặc [🛒] để thêm sản phẩm vào giỏ hàng. 4. Chọn vào [Xác nhận đơn] để đến trang nhập thông tin và đặt hàng | D25: 1. Để trống một hoặc nhiều trường bắt buộc (ví dụ: địa chỉ giao hàng hoặc phương thức thanh toán). 2. Nhấn nút [Đặt hàng]. | F25: Hiển thị thông báo lỗi: "Vui lòng điền đầy đủ các trường thông tin bắt buộc." | G25: None | H25: Passed | I25: 15/12/2024
A26: ORD_Check_009 | B26: Kiểm tra người dùng có thể chọn phương thức thanh toán và hiển thị đúng | C26: 1. Truy cập vào trang web: ""https://fptshop.com.vn/"" thành công 2. Chọn vào sản phẩm cần mua 3. Chọn vào [Mua ngay] hoặc [🛒] để thêm sản phẩm vào giỏ hàng. 4. Chọn vào [Xác nhận đơn] để đến trang nhập thông tin và đặt hàng | D26: 1. Điều hướng đến trang thanh toán. 2. Chọn từng phương thức thanh toán (ATM, thanh toán khi nhận hàng hoặc ví điện tử). 3. Xác minh phương thức hiển thị đúng trong phần tóm tắt đơn hàng. | F26: Phương thức thanh toán được hiển thị chính xác trong phần tóm tắt đơn hàng. | G26: None | H26: Passed | I26: 15/12/2024 | J26: Kiểm tra trường hợp không chọn phương thức thanh toán.
A27: ORD_Check_010 | B27: Kiểm tra hệ thống ngăn cản áp dụng lại mã giảm giá đã sử dụng. | C27: 1. Truy cập vào trang web: ""https://fptshop.com.vn/"" thành công 2. Chọn vào sản phẩm cần mua 3. Chọn vào [Mua ngay] hoặc [🛒] để thêm sản phẩm vào giỏ hàng. 4. Chọn vào [Xác nhận đơn] để đến trang nhập thông tin và đặt hàng | D27: 1. Nhập mã giảm giá đã sử dụng. 2. Nhấn nút [Áp dụng mã]. 3. Xác minh rằng hệ thống hiển thị thông báo lỗi. | E27: Mã giảm giá: SAVE20 - Giá trị giảm giá: 20% | F27: Hiển thị thông báo lỗi: "Mã giảm giá đã được sử dụng." | G27: Depends on ORD_Add_002 | H27: Failed | I27: 15/12/2024
A28: ORD_Check_011 | B28: Kiểm tra tổng giá tiền cập nhật đúng khi áp dụng mã giảm giá hợp lệ | C28: 1. Truy cập vào trang web: ""https://fptshop.com.vn/"" thành công 2. Chọn vào sản phẩm cần mua 3. Chọn vào [Mua ngay] hoặc [🛒] để thêm sản phẩm vào giỏ hàng. 4. Chọn vào [Xác nhận đơn] để đến trang nhập thông tin và đặt hàng | D28: 1. Điều hướng đến trang giỏ hàng. 2. Nhập mã giảm giá hợp lệ và nhấn [Áp dụng]. 3. Kiểm tra tổng giá tiền sau khi áp dụng mã giảm giá. | E28: Mã giảm giá: SAVE20 - Giá trị giảm giá: 20% | F28: Tổng giá tiền được hiển thị chính xác sau khi áp dụng mã giảm giá. | G28: None | H28: Failed | I28: 15/12/2024 | J28: Cũng kiểm tra trường hợp mã giảm giá hết hạn.
A29: ORD_Check_012 | B29: Kiểm tra hệ thống ngăn cản phương thức thanh toán hết hạn | C29: 1. Truy cập vào trang web: ""https://fptshop.com.vn/"" thành công 2. Chọn vào sản phẩm cần mua 3. Chọn vào [Mua ngay] hoặc [🛒] để thêm sản phẩm vào giỏ hàng. 4. Chọn vào [Xác nhận đơn] để đến trang nhập thông tin và đặt hàng | D29: 1. Nhập thông tin thẻ đã hết hạn. 2. Nhấn nút [Đặt hàng]. | E29: Số thẻ:123456712123111 - Ngày hết hạn: 12/25 - CVV: 123 | F29: Hiển thị thông báo lỗi: "Thẻ bạn đã nhập đã hết hạn." | G29: None | H29: Passed | I29: 15/12/2024
A30: ORD_Check_013 | B30: Kiểm tra sau khi nhập tất cả thông tin thì có thể đặt hàng thành công | C30: 1. Truy cập vào trang web: ""https://fptshop.com.vn/"" thành công 2. Chọn vào sản phẩm cần mua 3. Chọn vào [Mua ngay] hoặc [🛒] để thêm sản phẩm vào giỏ hàng. 4. Chọn vào [Xác nhận đơn] để đến trang nhập thông tin và đặt hàng | D30: 1. Hoàn tất tất cả các trường thông tin bắt buộc. 2. Nhấn nút [Đặt hàng].. | F30: Người dùng được chuyển hướng đến màn hình xác nhận đơn hàng sau khi đặt hàng thành công. | G30: Depends on ORD_Check_007 | H30: Passed | I30: 15/12/2024
A31: ORD_Check_014 | B31: Kiểm tra khách hàng phải đồng ý điều khoản trước khi đặt hàng | C31: 1. Truy cập vào trang web: ""https://fptshop.com.vn/"" thành công 2. Chọn vào sản phẩm cần mua 3. Chọn vào [Mua ngay] hoặc [🛒] để thêm sản phẩm vào giỏ hàng. 4. Chọn vào [Xác nhận đơn] để đến trang nhập thông tin và đặt hàng | D31: 1. Điều hướng đến trang xác nhận đơn hàng. 2. Không chọn hộp kiểm "Đồng ý với điều khoản". 3. Thử đặt hàng bằng cách nhấn nút [Đặt hàng]. | F31: Hiển thị thông báo lỗi: "Bạn phải đồng ý với các điều khoản trước khi đặt hàng." | G31: None | H31: Failed | I31: 15/12/2024 | J31: Yêu cầu đồng ý điều khoản.
A32: ORD_Check_015 | B32: Kiểm tra người dùng có thể chọn địa điểm lấy hàng | C32: 1. Truy cập vào trang web: ""https://fptshop.com.vn/"" thành công 2. Chọn vào sản phẩm cần mua 3. Chọn vào [Mua ngay] hoặc [🛒] để thêm sản phẩm vào giỏ hàng. 4. Chọn vào [Xác nhận đơn] để đến trang nhập thông tin và đặt hàng | D32: 1. Điều hướng đến tùy chọn giao hàng. 2. Chọn "Nhận tại cửa hàng". 3. Chọn một cửa hàng trong danh sách. | F32: Người dùng có thể chọn địa điểm lấy hàng. | G32: Depends on ORD_Add_003 | H32: Passed | I32: 15/12/2024 | J32: Cửa hàng phải khả dụng.
A33: ORD_Check_016 | B33: Kiểm tra không thể chọn cửa hàng không hợp lệ | C33: 1. Truy cập vào trang web: ""https://fptshop.com.vn/"" thành công 2. Chọn vào sản phẩm cần mua 3. Chọn vào [Mua ngay] hoặc [🛒] để thêm sản phẩm vào giỏ hàng. 4. Chọn vào [Xác nhận đơn] để đến trang nhập thông tin và đặt hàng | D33: 1. Điều hướng đến tùy chọn giao hàng. 2. Thử chọn một cửa hàng không khả dụng. | F33: Hiển thị thông báo lỗi: "Cửa hàng này không khả dụng để nhận hàng." | G33: None | H33: Failed | I33: 15/12/2024 | J33: Kiểm tra tính khả dụng của cửa hàng.
A34: ORD_Check_017 | B34: Kiểm tra tính hợp lệ của ngày và khung giờ giao hàng | C34: 1. Truy cập vào trang web: ""https://fptshop.com.vn/"" thành công 2. Chọn vào sản phẩm cần mua 3. Chọn vào [Mua ngay] hoặc [🛒] để thêm sản phẩm vào giỏ hàng. 4. Chọn vào [Xác nhận đơn] để đến trang nhập thông tin và đặt hàng | D34: 1. Điều hướng đến tùy chọn giao hàng. 2. Chọn ngày và khung giờ giao hàng. 3. Kiểm tra tính hợp lệ của khung giờ đã chọn. | F34: Ngày và khung giờ giao hàng hợp lệ và khả dụng | G34: Depends on ORD_Add_004 | H34: Passed | I34: 15/12/2024
A35: ORD_Check_018 | B35: Kiểm tra không thể sử dụng điểm thưởng hết hạn | C35: 1. Truy cập vào trang web: ""https://fptshop.com.vn/"" thành công 2. Chọn vào sản phẩm cần mua 3. Chọn vào [Mua ngay] hoặc [🛒] để thêm sản phẩm vào giỏ hàng. 4. Chọn vào [Xác nhận đơn] để đến trang nhập thông tin và đặt hàng | D35: 1. Đăng nhập vào tài khoản có điểm thưởng hết hạn. 2. Cố gắng sử dụng điểm thưởng trong quá trình thanh toán. | F35: Hiển thị thông báo lỗi: "Điểm thưởng của bạn đã hết hạn." | G35: None | H35: Failed | I35: 15/12/2024
A36: ORD_Check_019 | B36: Kiểm tra không thể sử dụng đồng thời điểm thưởng và mã giảm giá | C36: 1. Truy cập vào trang web: ""https://fptshop.com.vn/"" thành công 2. Chọn vào sản phẩm cần mua 3. Chọn vào [Mua ngay] hoặc [🛒] để thêm sản phẩm vào giỏ hàng. 4. Chọn vào [Xác nhận đơn] để đến trang nhập thông tin và đặt hàng | D36: 1. Đăng nhập vào tài khoản có điểm thưởng. 2. Nhập mã giảm giá hợp lệ. 3. Thử sử dụng đồng thời điểm thưởng và mã giảm giá. | E36: Mã giảm giá: SAVE20 - Giá trị giảm giá: 20% | F36: Hiển thị thông báo lỗi: "Chỉ có thể áp dụng một mã giảm giá tại một thời điểm." | G36: Depends on ORD_Add_002 | H36: Failed | I36: 15/12/2024 | J36: Ràng buộc được áp dụng.
A37: ORD_Check_020 | B37: Kiểm tra có thể cập nhật phương thức thanh toán sau đánh giá đơn hàng | C37: 1. Truy cập vào trang web: ""https://fptshop.com.vn/"" thành công 2. Chọn vào sản phẩm cần mua 3. Chọn vào [Mua ngay] hoặc [🛒] để thêm sản phẩm vào giỏ hàng. 4. Chọn vào [Xác nhận đơn] để đến trang nhập thông tin và đặt hàng | D37: 1. Hoàn tất quá trình đánh giá đơn hàng. 2. Thay đổi phương thức thanh toán. 3. Tiến hành với phương thức thanh toán mới. | F37: Phương thức thanh toán mới được áp dụng thành công. | G37: Depends on ORD_Edit_001 | H37: Passed | I37: 15/12/2024
A38: ORD_Check_021 | B38: Kiểm tra hệ thống chặn thông tin thẻ không hợp lệ | C38: 1. Truy cập vào trang web: ""https://fptshop.com.vn/"" thành công 2. Chọn vào sản phẩm cần mua 3. Chọn vào [Mua ngay] hoặc [🛒] để thêm sản phẩm vào giỏ hàng. 4. Chọn vào [Xác nhận đơn] để đến trang nhập thông tin và đặt hàng | D38: 1. Nhập thông tin thẻ tín dụng không hợp lệ (ví dụ: số thẻ sai, ngày hết hạn sai). 2. Thử đặt hàng bằng cách nhấn nút [Đặt hàng]. | E38: Số thẻ:123456712123111 - Ngày hết hạn: 12/25 - CVV: 123 | F38: Hiển thị thông báo lỗi: "Thông tin thẻ không hợp lệ." | G38: None | H38: Failed | I38: 15/12/2024
A39: ORD_Check_022 | B39: Kiểm tra thông báo xác nhận thanh toán sau khi thành công | C39: 1. Truy cập vào trang web: ""https://fptshop.com.vn/"" thành công 2. Chọn vào sản phẩm cần mua 3. Chọn vào [Mua ngay] hoặc [🛒] để thêm sản phẩm vào giỏ hàng. 4. Chọn vào [Xác nhận đơn] để đến trang nhập thông tin và đặt hàng | D39: 1. Chọn phương thức thanh toán hợp lệ. 2. Hoàn tất thanh toán. 3. Kiểm tra nếu hệ thống hiển thị thông báo xác nhận thanh toán. | F39: Thông báo xác nhận hiển thị: "Thanh toán của bạn đã thành công." | G39: Depends on ORD_Check_018 | H39: Failed | I39: 15/12/2024
A40: ORD_Check_023 | B40: Kiểm tra phí giao hàng được tính toán chính xác và thêm vào tổng giá | C40: 1. Truy cập vào trang web: ""https://fptshop.com.vn/"" thành công 2. Chọn vào sản phẩm cần mua 3. Chọn vào [Mua ngay] hoặc [🛒] để thêm sản phẩm vào giỏ hàng. 4. Chọn vào [Xác nhận đơn] để đến trang nhập thông tin và đặt hàng | D40: 1. Chọn phương thức giao hàng (ví dụ: "Giao hàng tận nơi"). 2. Kiểm tra tổng giá hiển thị, bao gồm cả phí giao hàng. | F40: Tổng giá được cập nhật chính xác bao gồm phí giao hàng. | G40: Depends on ORD_Check_019 | H40: Passed | I40: 15/12/2024
A41: ORD_Check_024 | B41: Kiểm tra hệ thống cho phép xác nhận đơn hàng với mọi phương thức thanh toán hợp lệ | C41: 1. Truy cập vào trang web: ""https://fptshop.com.vn/"" thành công 2. Chọn vào sản phẩm cần mua 3. Chọn vào [Mua ngay] hoặc [🛒] để thêm sản phẩm vào giỏ hàng. 4. Chọn vào [Xác nhận đơn] để đến trang nhập thông tin và đặt hàng | D41: 1. Hoàn tất quá trình đặt hàng với một phương thức thanh toán hợp lệ (thẻ tín dụng, ví điện tử, v.v.). 2. Xác minh rằng hệ thống xác nhận đơn hàng. | E41: Số thẻ:123456712123111 - Ngày hết hạn: 12/25 - CVV: 123 | F41: Xác nhận đơn hàng hiển thị thành công. | G41: Depends on ORD_Check_019 | H41: Failed | I41: 15/12/2024 | J41: Tất cả phương thức thanh toán hợp lệ.
A42: ORD_Check_025 | B42: Kiểm tra thông báo lỗi khi chọn phương thức thanh toán không hợp lệ | C42: 1. Truy cập vào trang web: ""https://fptshop.com.vn/"" thành công 2. Chọn vào sản phẩm cần mua 3. Chọn vào [Mua ngay] hoặc [🛒] để thêm sản phẩm vào giỏ hàng. 4. Chọn vào [Xác nhận đơn] để đến trang nhập thông tin và đặt hàng | D42: 1. Thử đặt hàng bằng phương thức thanh toán không hợp lệ (thẻ đã hết hạn, ví điện tử không hợp lệ). 2. Xác minh nếu hệ thống từ chối thanh toán. | F42: Hiển thị thông báo lỗi: "Phương thức thanh toán không hợp lệ." | G42: Depends on ORD_Check_018 | H42: Failed | I42: 15/12/2024 | J42: Phương thức thanh toán không hợp lệ.
...

Sheet Test Report
B1: TEST REPORT
B3: Project Name | C3: =Cover!C4 -> FPT-SHOP | E3: Creator | G3: Nguyễn Văn A
B4: Project Code | C4: =Cover!C5 -> FPT-SHOP | E4: Reviewer/Approver | G4: Trần Thụy Minh Thư
B5: Document Code | C5: =C4&"_"&"Test Report"&"" -> FPT-SHOP_Test Report | E5: Issue Date | G5: 15/12/2024
B6: Notes
B10: No | C10: Module code | D10: Pass | E10: Fail | F10: Untested | G10: Blocked | H10: Skipped | I10: Number of test cases
B11: 1 | C11: =[1]ConfirmOrder!B2 -> ConfirmOrder | D11: =[1]ConfirmOrder!A6 -> 27 | E11: =[1]ConfirmOrder!B6 -> 23 | F11: =[1]ConfirmOrder!D6 -> 0 | G11: =[1]ConfirmOrder!F6 -> 0 | H11: =[1]ConfirmOrder!G6 -> 0 | I11: =[1]ConfirmOrder!H6 -> 50
C13: Sub total | D13: =SUM(D9:D11) -> 27 | E13: =SUM(E9:E11) -> 23 | F13: =SUM(F9:F11) -> 0 | G13: =SUM(G9:G11) -> 0 | H13: =SUM(H9:H11) -> 0 | I13: =SUM(I9:I11) -> 50
C15: Test coverage | E15: =(D13+E13)*100/(I13-H13-G13) -> 100 | F15: %
C16: Test successful coverage | E16: =D13*100/(D13+E13) -> 54 | F16: %

Sheet Defect Report 
A1: Environment | B1: Test
A2: Release Name | B2: 20150115141605
A3: Date | B3: 42017
A4: FPT QA Name | B4: Nguyen Van A
A6: Defect ID | B6: Defect Description & Steps to reproduce | C6: Actual Result | D6: Expected Result | E6: Priority | F6: Serverity | G6: Testcase ID
A7: #DFORD1 | B7: [Đặt hàng][Mã giảm giá] Lỗi: Mã giảm giá hợp lệ không được áp dụng thành công.
B8: Pre-condition: Đăng nhập vào hệ thống, giỏ hàng có ít nhất một sản phẩm, và mã giảm giá (SAVE20) hợp lệ. Steps: 1. Điều hướng đến trang thanh toán. 2. Nhấn vào nút "Chọn hoặc nhập ưu đãi" để mở khung nhập mã giảm giá. 3. Nhập mã giảm giá hợp lệ (SAVE20). 4. Nhấn nút "Xác nhận". 5. Quan sát tổng tiền và phần giảm giá trong thông tin đơn hàng. | C8: Mã giảm giá không được áp dụng. Tổng tiền vẫn giữ nguyên, phần giảm giá không hiển thị trên thông tin đơn hàng. | D8: Mã giảm giá phải được áp dụng thành công. Tổng tiền cần giảm tương ứng 20%, và phần giảm giá cần hiển thị trong thông tin đơn hàng. | E8: High | F8: Critical | G8: ORD_Add_200
A9: #DFORD2 | B9: [Đặt hàng][Thêm phương thức thanh toán] Lỗi: Phương thức thanh toán bằng thẻ tín dụng không được thêm thành công.
B10: Pre-condition: Đăng nhập vào hệ thống, điều hướng đến trang thanh toán. Steps: 1. Điều hướng đến trang thanh toán. 2. Nhập thông tin thẻ tín dụng hợp lệ (số thẻ: 123456712123111, ngày hết hạn: 12/25, CVV: 123). 3. Nhấn nút [Thêm phương thức thanh toán]. 4. Xác minh phương thức thanh toán được thêm thành công. | C10: Giao diện hiển thị thông báo: "Thẻ không hỗ trợ". Người dùng không thể thêm phương thức thanh toán mặc dù thông tin thẻ hợp lệ. | D10: Phương thức thanh toán phải được thêm thành công. Giao diện cần hiển thị xác nhận và phương thức thanh toán cần hiển thị trong danh sách đã lưu. | E10: High | F10: Critical | G10: ORD_Add_700
A11: #DFORD3 | B11: [Đặt hàng][Thêm điểm thưởng vào đơn hàng] Lỗi: Điểm thưởng không được áp dụng thành công.
B12: Pre-condition: Đăng nhập vào tài khoản có điểm thưởng. Steps: 1. Đăng nhập vào tài khoản có điểm thưởng. 2. Điều hướng đến trang thanh toán. 3. Áp dụng điểm thưởng vào đơn hàng. 4. Xác minh điểm thưởng được áp dụng chính xác. | C12: Giao diện hiển thị thông báo: "Bạn không đủ điều kiện để sử dụng điểm thưởng". Tổng tiền không được giảm tương ứng với giá trị điểm thưởng đã áp dụng | D12: Điểm thưởng phải được áp dụng thành công. Tổng tiền cần giảm tương ứng đúng với giá trị điểm thưởng đã sử dụng. | E12: Medium | F12: Major | G12: ORD_Add_800
A13: #DFORD4 | B13: [Đặt hàng][Mã giảm giá] Lỗi: Mã giảm giá hợp lệ không được áp dụng thành công.
B14: Pre-condition: Đăng nhập vào hệ thống, giỏ hàng có ít nhất một sản phẩm, và mã giảm giá (SAVE20) hợp lệ. Steps: 1. Điều hướng đến trang thanh toán. 2. Nhấn vào nút "Chọn hoặc nhập ưu đãi" để mở khung nhập mã giảm giá. 3. Nhập mã giảm giá hợp lệ (SAVE20). 4. Nhấn nút "Xác nhận". 5. Quan sát tổng tiền và phần giảm giá trong thông tin đơn hàng. | C14: Mã giảm giá không được áp dụng. Tổng tiền vẫn giữ nguyên, phần giảm giá không hiển thị trên thông tin đơn hàng. | D14: Cần hiển thị thông báo lỗi: "Mã giảm giá không hợp lệ hoặc đã hết hạn". | E14: High | F14: Critical | G14: ORD_Add_600
A15: #DFORD5 | B15: [Đặt hàng][Kiểm tra mã giảm giá] Lỗi: Không hiển thị thông báo lỗi khi mã giảm giá không hợp lệ hoặc đã hết hạn.
B16: Pre-condition: Hệ thống có hỗ trợ mã giảm giá. Steps: 1. Nhập mã giảm giá hết hạn hoặc không hợp lệ (SAVE20). 2. Nhấn nút [Áp dụng mã]. | C16: Không hiển thị thông báo lỗi. Giao diện không đưa ra bất kỳ phản hồi nào khi mã giảm giá không hợp lệ hoặc hết hạn. | D16: Cần hiển thị thông báo lỗi: "Mã giảm giá không hợp lệ hoặc đã hết hạn". | E16: High | F16: Medium | G16: ORD_Check_003
A17: #DFORD6 | B17: [Đặt hàng][Kiểm tra mã giảm giá] Lỗi: Hệ thống không ngăn cản việc áp dụng lại mã giảm giá đã sử dụng.
B18: Pre-condition: Mã giảm giá đã được sử dụng trước đó. Steps: 1. Nhập mã giảm giá đã sử dụng (SAVE20). 2. Nhấn nút [Áp dụng mã]. 3. Xác minh rằng hệ thống hiển thị thông báo lỗi. | C18: Hệ thống không hiển thị thông báo lỗi. Người dùng có thể áp dụng lại mã giảm giá đã sử dụng. | D18: Hệ thống cần hiển thị thông báo lỗi: "Mã giảm giá đã được sử dụng". | E18: Medium | F18: Major | G18: ORD_Check_010
A19: #DFORD7 | B19: [Đặt hàng][Kiểm tra tổng giá tiền] Lỗi: Tổng giá tiền không được cập nhật đúng sau khi áp dụng mã giảm giá hợp lệ.
B20: Pre-condition: there are at least one active organisation which name starts with letter "N" in database. Steps:Pre-condition: Mã giảm giá hợp lệ (SAVE20). Steps: 1. Điều hướng đến trang giỏ hàng. 2. Nhập mã giảm giá hợp lệ và nhấn [Áp dụng]. 3. Kiểm tra tổng giá tiền sau khi áp dụng mã giảm giá. | C20: Tổng giá tiền không được cập nhật đúng sau khi áp dụng mã giảm giá. | D20: Tổng giá tiền phải được hiển thị chính xác sau khi áp dụng mã giảm giá. | E20: High | F20: Medium | G20: ORD_Check_011
A21: #DFORD8 | B21: [Đặt hàng][Kiểm tra điều khoản] Lỗi: Hệ thống không hiển thị thông báo lỗi khi khách hàng không đồng ý với điều khoản trước khi đặt hàng.
B22: Pre-condition: Đơn hàng ở trạng thái sẵn sàng xác nhận. Steps: 1. Điều hướng đến trang xác nhận đơn hàng. 2. Không chọn hộp kiểm "Đồng ý với điều khoản". 3. Nhấn nút [Đặt hàng]. | C22: Hệ thống không hiển thị thông báo lỗi. Khách hàng có thể tiến hành đặt hàng mà không đồng ý với điều khoản. | D22: Hệ thống cần hiển thị thông báo lỗi: "Bạn phải đồng ý với các điều khoản trước khi đặt hàng". | E22: Medium | F22: Major | G22: ORD_Check_014
A23: #DFORD9 | B23: [Đặt hàng][Kiểm tra cửa hàng khả dụng] Lỗi: Hệ thống không hiển thị thông báo lỗi khi người dùng chọn cửa hàng không khả dụng.
B24: Pre-condition: Một số cửa hàng không khả dụng để nhận hàng. Steps: 1. Điều hướng đến tùy chọn giao hàng. 2. Thử chọn một cửa hàng không khả dụng. | C24: Hệ thống không hiển thị thông báo lỗi. Người dùng có thể chọn cửa hàng không khả dụng để nhận hàng. | D24: Hệ thống cần hiển thị thông báo lỗi: "Cửa hàng này không khả dụng để nhận hàng". | E24: Medium | F24: Major | G24: ORD_Check_016
A25: #DFORD10 | B25: [Đặt hàng][Kiểm tra điểm thưởng hết hạn] Lỗi: Hệ thống không hiển thị thông báo lỗi khi cố gắng sử dụng điểm thưởng đã hết hạn.
B26: Pre-condition: Tài khoản có điểm thưởng hết hạn. Steps: 1. Đăng nhập vào tài khoản có điểm thưởng hết hạn. 2. Cố gắng sử dụng điểm thưởng trong quá trình thanh toán. | C26: Hệ thống không hiển thị thông báo lỗi. Người dùng có thể tiếp tục quy trình thanh toán mà không nhận được thông báo về trạng thái hết hạn của điểm thưởng. | D26: Hệ thống cần hiển thị thông báo lỗi: "Điểm thưởng của bạn đã hết hạn". | E26: Medium | F26: Major | G26: ORD_Check_018
A27: #DFORD11 | B27: [Đặt hàng][Kiểm tra sử dụng đồng thời điểm thưởng và mã giảm giá] Lỗi: Hệ thống không hạn chế việc áp dụng đồng thời điểm thưởng và mã giảm giá.
B28: Pre-condition: Tài khoản có điểm thưởng và hệ thống hỗ trợ mã giảm giá hợp lệ. Steps: 1. Đăng nhập vào tài khoản có điểm thưởng. 2. Nhập mã giảm giá hợp lệ. 3. Cố gắng sử dụng đồng thời điểm thưởng và mã giảm giá. | C28: Hệ thống không hiển thị thông báo lỗi. Người dùng có thể sử dụng cả điểm thưởng và mã giảm giá trong cùng một lần thanh toán. | D28: Hệ thống cần hiển thị thông báo lỗi: "Chỉ có thể áp dụng một mã giảm giá tại một thời điểm". | E28: High | F28: Critical | G28: ORD_Check_019
A29: #DFORD12 | B29: [Đặt hàng][Kiểm tra thẻ tín dụng không hợp lệ] Lỗi: Hệ thống không chặn thông tin thẻ tín dụng không hợp lệ.
B30: Pre-condition: Tài khoản có thể thêm thông tin thẻ tín dụng. Steps: 1. Nhập thông tin thẻ tín dụng không hợp lệ (ví dụ: số thẻ sai, ngày hết hạn sai). 2. Thử đặt hàng bằng cách nhấn nút [Đặt hàng]. | C30: Hệ thống không hiển thị thông báo lỗi. Người dùng có thể tiếp tục quá trình thanh toán với thông tin thẻ không hợp lệ. | D30: Hệ thống cần hiển thị thông báo lỗi: "Thông tin thẻ không hợp lệ". | E30: High | F30: Critical | G30: ORD_Check_021
A31: #DFORD13 | B31: [Đặt hàng][Kiểm tra xác nhận thanh toán] Lỗi: Hệ thống không hiển thị thông báo xác nhận sau khi thanh toán thành công.
B32: Pre-condition: Phương thức thanh toán hợp lệ được chọn. Steps: 1. Chọn phương thức thanh toán hợp lệ. 2. Hoàn tất thanh toán. 3. Kiểm tra nếu hệ thống hiển thị thông báo xác nhận thanh toán. | C32: Hệ thống không hiển thị thông báo xác nhận thanh toán. Người dùng không nhận được thông tin xác nhận giao dịch đã hoàn tất. | D32: Hệ thống cần hiển thị thông báo xác nhận: "Thanh toán của bạn đã thành công". | E32: Medium | F32: Major | G32: ORD_Check_022
A33: #DFORD14 | B33: [Đặt hàng][Xác nhận đơn hàng với phương thức thanh toán hợp lệ] Lỗi: Hệ thống không cho phép xác nhận đơn hàng với phương thức thanh toán hợp lệ.
B34: Pre-condition: Có ít nhất một phương thức thanh toán hợp lệ. Steps: 1. Hoàn tất quá trình đặt hàng với một phương thức thanh toán hợp lệ (thẻ tín dụng, ví điện tử, v.v.). 2. Xác minh rằng hệ thống xác nhận đơn hàng. | C34: Hệ thống không hiển thị xác nhận đơn hàng. Người dùng không nhận được thông báo xác nhận sau khi hoàn tất thanh toán bằng phương thức hợp lệ. | D34: Xác nhận đơn hàng cần được hiển thị thành công. | E34: High | F34: Critical | G34: ORD_Check_024
A35: #DFORD15 | B35: [Đặt hàng][Kiểm tra phương thức thanh toán không hợp lệ] Lỗi: Hệ thống không hiển thị thông báo lỗi khi chọn phương thức thanh toán không hợp lệ.
B36: Pre-condition: Chọn phương thức thanh toán không hợp lệ (ví dụ: thẻ hết hạn, ví điện tử không hợp lệ). Steps: 1. Thử đặt hàng bằng phương thức thanh toán không hợp lệ. 2. Xác minh nếu hệ thống từ chối thanh toán. | C36: Hệ thống không hiển thị thông báo lỗi. Người dùng có thể tiếp tục quy trình thanh toán với phương thức không hợp lệ. | D36: Hệ thống cần hiển thị thông báo lỗi: "Phương thức thanh toán không hợp lệ". | E36: High | F36: Major | G36: ORD_Check_025
A37: #DFORD16 | B37: [Đặt hàng][Kiểm tra mã giảm giá hết hạn] Lỗi: Hệ thống không hiển thị thông báo lỗi hợp lệ khi áp dụng mã giảm giá hết hạn.
B38: Pre-condition: Mã giảm giá đã hết hạn. Steps: 1. Áp dụng mã giảm giá hết hạn trong quá trình thanh toán. 2. Thử xác nhận đơn hàng. | C38: Hệ thống không hiển thị thông báo lỗi. Người dùng có thể áp dụng mã giảm giá hết hạn mà không nhận được cảnh báo hoặc từ chối. | D38: Hệ thống cần hiển thị thông báo lỗi: "Mã giảm giá này đã hết hạn". | E38: Medium | F38: Major | G38: ORD_Check_029
A39: #DFORD17 | B39: [Đặt hàng][Cập nhật địa chỉ giao hàng] Lỗi: Hệ thống không cập nhật thành công địa chỉ giao hàng trong quá trình thanh toán.
B40: Pre-condition: Người dùng có quyền thay đổi địa chỉ giao hàng trong quá trình thanh toán. Steps: 1. Tại quá trình thanh toán, thay đổi địa chỉ giao hàng. 2. Xác minh rằng hệ thống lưu và cập nhật địa chỉ mới. | C40: Địa chỉ giao hàng không được cập nhật. Giao diện vẫn hiển thị địa chỉ cũ sau khi thay đổi. | D40: Địa chỉ giao hàng cần được cập nhật thành công và hiển thị địa chỉ mới. | E40: Medium | F40: Major | G40: ORD_Check_031
A41: #DFORD18 | B41: [Đặt hàng][Chỉnh sửa phương thức thanh toán] Lỗi: Hệ thống không cho phép chỉnh sửa thông tin phương thức thanh toán thành công.
...
